<sdf version='1.4'>
  <model name='autobed'>
    <link name='base_link'>
      <pose>1.070000 -0.000000 0.000000 0.000000 0.000000 0.000000</pose>
      <inertial>
        <pose>1.070000 -0.000000 0.000000 0.000000 0.000000 0.000000</pose>
        <mass>582.602000</mass>
        <inertia>
          <ixx>1.149270</ixx>
          <ixy>0.000000</ixy>
          <ixz>-0.000000</ixz>
          <iyy>6.704340</iyy>
          <iyz>-0.000000</iyz>
          <izz>7.797550</izz>
        </inertia>
      </inertial>
      <collision name='base_link_collision'>
        <pose>0.000000 0.000000 0.000000 0.000000 0.000000 0.000000</pose>
        <geometry>
          <mesh>
            <scale>1.000000 1.000000 1.000000</scale>
            <uri>model://autobed/meshes/base_link.STL</uri>
          </mesh>
        </geometry>
      </collision>
      <visual name='base_link_vis'>
        <pose>0.000000 0.000000 0.000000 0.000000 0.000000 0.000000</pose>
        <geometry>
          <mesh>
            <scale>1.000000 1.000000 1.000000</scale>
            <uri>model://autobed/meshes/base_link.STL</uri>
          </mesh>
        </geometry>
      </visual>
      <velocity_decay>
        <linear>0.000000</linear>
        <angular>0.000000</angular>
      </velocity_decay>
    </link>
    <joint name='X' type='revolute'>
      <child>base_link</child>
      <parent>world</parent>
      <axis>
        <limit>
          <lower>0.000000</lower>
          <upper>0.000000</upper>
        </limit>
        <dynamics>
          <damping>0.000000</damping>
        </dynamics>
        <xyz>0.000000 0.000000 1.000000</xyz>
      </axis>
    </joint>
    <link name='bed_frame_link'>
      <pose>1.050000 -0.000000 0.280500 0.000000 0.000000 0.000000</pose>
      <inertial>
        <pose>1.038490 0.000000 0.093093 0.000000 0.000000 0.000000</pose>
        <mass>18.278300</mass>
        <inertia>
          <ixx>14.172700</ixx>
          <ixy>0.000000</ixy>
          <ixz>-0.582879</ixz>
          <iyy>75.805800</iyy>
          <iyz>0.000000</iyz>
          <izz>86.690600</izz>
        </inertia>
      </inertial>
      <collision name='bed_frame_link_collision'>
        <pose>0.000000 0.000000 0.000000 0.000000 0.000000 0.000000</pose>
        <geometry>
          <mesh>
            <scale>1.000000 1.000000 1.000000</scale>
            <uri>model://autobed/meshes/bed_frame_link.STL</uri>
          </mesh>
        </geometry>
        <surface>
          <contact>
            <ode/>
          </contact>
          <friction>
            <ode>
              <mu>0.010000</mu>
              <mu2>0.010000</mu2>
            </ode>
          </friction>
        </surface>
      </collision>
      <visual name='bed_frame_link_vis'>
        <pose>0.000000 0.000000 0.000000 0.000000 0.000000 0.000000</pose>
        <geometry>
          <mesh>
            <scale>1.000000 1.000000 1.000000</scale>
            <uri>model://autobed/meshes/bed_frame_link.STL</uri>
          </mesh>
        </geometry>
      </visual>
      <gravity>1</gravity>
      <velocity_decay>
        <linear>0.000000</linear>
        <angular>0.000000</angular>
      </velocity_decay>
      <self_collide>0</self_collide>
      <sensor name='_tactile_sensor' type='contact'>
        <contact>
          <collision>bed_frame_link_collision</collision>
          <topic>__default_topic__</topic>
        </contact>
        <plugin name='ros_tactile_plugin_bed_frame' filename='libros_tactile_plugin.so'/>
        <always_on>1</always_on>
        <update_rate>30.000000</update_rate>
        <visualize>0</visualize>
      </sensor>
    </link>
    <joint name='autobed_height_joint' type='prismatic'>
      <child>bed_frame_link</child>
      <parent>base_link</parent>
      <axis>
        <xyz>0.000000 0.000000 1.000000</xyz>
        <limit>
          <lower>0.090000</lower>
          <upper>0.200000</upper>
          <effort>2000.000000</effort>
          <velocity>0.200000</velocity>
        </limit>
        <dynamics/>
      </axis>
    </joint>
    <link name='head_rest_link'>
      <pose>1.825000 -0.000000 0.540500 1.570800 0.000000 -3.141590</pose>
      <inertial>
        <pose>0.372570 -0.093354 -0.000000 0.000000 0.000000 0.000000</pose>
        <mass>15.215400</mass>
        <inertia>
          <ixx>11.333600</ixx>
          <ixy>0.223421</ixy>
          <ixz>-0.000000</ixz>
          <iyy>16.942100</iyy>
          <iyz>-0.000000</iyz>
          <izz>7.044560</izz>
        </inertia>
      </inertial>
      <collision name='head_rest_link_collision'>
        <pose>0.000000 0.000000 0.000000 0.000000 0.000000 0.000000</pose>
        <geometry>
          <mesh>
            <scale>1.000000 1.000000 1.000000</scale>
            <uri>model://autobed/meshes/head_rest_link.STL</uri>
          </mesh>
        </geometry>
        <surface>
          <contact>
            <ode/>
          </contact>
          <friction>
            <ode>
              <mu>0.010000</mu>
              <mu2>0.010000</mu2>
            </ode>
          </friction>
        </surface>
      </collision>
      <visual name='head_rest_link_vis'>
        <pose>0.000000 0.000000 0.000000 0.000000 0.000000 0.000000</pose>
        <geometry>
          <mesh>
            <scale>1.000000 1.000000 1.000000</scale>
            <uri>model://autobed/meshes/head_rest_link.STL</uri>
          </mesh>
        </geometry>
      </visual>
      <gravity>1</gravity>
      <velocity_decay>
        <linear>0.000000</linear>
        <angular>0.000000</angular>
      </velocity_decay>
      <self_collide>0</self_collide>
      <sensor name='_tactile_sensor' type='contact'>
        <contact>
          <collision>head_rest_link_collision</collision>
          <topic>__default_topic__</topic>
        </contact>
        <plugin name='ros_tactile_plugin_head_rest' filename='libros_tactile_plugin.so'/>
        <always_on>1</always_on>
        <update_rate>30.000000</update_rate>
        <visualize>0</visualize>
      </sensor>
    </link>
    <joint name='head_rest_hinge' type='revolute'>
      <child>head_rest_link</child>
      <parent>bed_frame_link</parent>
      <axis>
        <xyz>-0.000007 1.000000 -0.000004</xyz>
        <limit>
          <lower>0.000000</lower>
          <upper>1.057000</upper>
          <effort>2000.000000</effort>
          <velocity>0.200000</velocity>
        </limit>
        <dynamics/>
      </axis>
    </joint>
    <link name='leg_rest_upper_link'>
      <pose>2.105000 -0.000000 0.330500 1.570800 0.000000 0.000000</pose>
      <inertial>
        <pose>0.530000 0.105000 -0.000000 0.000000 0.000000 0.000000</pose>
        <mass>20.367900</mass>
        <inertia>
          <ixx>14.958900</ixx>
          <ixy>0.000000</ixy>
          <ixz>0.000000</ixz>
          <iyy>21.581700</iyy>
          <iyz>0.000000</iyz>
          <izz>8.119830</izz>
        </inertia>
      </inertial>
      <collision name='leg_rest_upper_link_collision'>
        <pose>0.000000 0.000000 0.000000 0.000000 0.000000 0.000000</pose>
        <geometry>
          <mesh>
            <scale>1.000000 1.000000 1.000000</scale>
            <uri>model://autobed/meshes/leg_rest_upper_link.STL</uri>
          </mesh>
        </geometry>
        <surface>
          <contact>
            <ode/>
          </contact>
          <friction>
            <ode>
              <mu>0.010000</mu>
              <mu2>0.010000</mu2>
            </ode>
          </friction>
        </surface>
      </collision>
      <collision name='leg_rest_upper_link_collision_leg_rest_lower_link'>
        <pose>0.370000 0.000000 0.000000 -0.000000 0.000000 0.000000</pose>
        <geometry>
          <mesh>
            <scale>1.000000 1.000000 1.000000</scale>
            <uri>model://autobed/meshes/leg_rest_lower_link.STL</uri>
          </mesh>
        </geometry>
        <surface>
          <contact>
            <ode/>
          </contact>
          <friction>
            <ode>
              <mu>0.010000</mu>
              <mu2>0.010000</mu2>
            </ode>
          </friction>
        </surface>
      </collision>
      <visual name='leg_rest_upper_link_vis'>
        <pose>0.000000 0.000000 0.000000 0.000000 0.000000 0.000000</pose>
        <geometry>
          <mesh>
            <scale>1.000000 1.000000 1.000000</scale>
            <uri>model://autobed/meshes/leg_rest_upper_link.STL</uri>
          </mesh>
        </geometry>
      </visual>
      <visual name='leg_rest_upper_link_vis_leg_rest_lower_link'>
        <pose>0.370000 0.000000 0.000000 -0.000000 0.000000 0.000000</pose>
        <geometry>
          <mesh>
            <scale>1.000000 1.000000 1.000000</scale>
            <uri>model://autobed/meshes/leg_rest_lower_link.STL</uri>
          </mesh>
        </geometry>
      </visual>
      <velocity_decay>
        <linear>0.000000</linear>
        <angular>0.000000</angular>
      </velocity_decay>
      <sensor name='_tactile_sensor' type='contact'>
        <contact>
          <collision>leg_rest_upper_link_collision</collision>
          <topic>__default_topic__</topic>
        </contact>
        <plugin name='ros_tactile_plugin_leg_rest_upper' filename='libros_tactile_plugin.so'/>
        <always_on>1</always_on>
        <update_rate>30.000000</update_rate>
        <visualize>0</visualize>
      </sensor>
      <gravity>1</gravity>
      <velocity_decay>
        <linear>0.000000</linear>
        <angular>0.000000</angular>
      </velocity_decay>
      <self_collide>0</self_collide>
      <sensor name='_tactile_sensor' type='contact'>
        <contact>
          <topic>__default_topic__</topic>
          <collision>leg_rest_upper_link_collision_leg_rest_lower_link</collision>
        </contact>
        <plugin name='ros_tactile_plugin_leg_rest_lower' filename='libros_tactile_plugin.so'/>
        <always_on>1</always_on>
        <update_rate>30.000000</update_rate>
        <visualize>0</visualize>
        <pose>0.370000 0.000000 0.000000 -0.000000 0.000000 0.000000</pose>
      </sensor>
    </link>
    <joint name='leg_rest_upper_joint' type='revolute'>
      <child>leg_rest_upper_link</child>
      <parent>bed_frame_link</parent>
      <axis>
        <xyz>0.000000 -1.000000 -0.000004</xyz>
        <limit>
          <lower>0.000000</lower>
          <upper>1.000000</upper>
          <effort>2000.000000</effort>
          <velocity>0.200000</velocity>
        </limit>
        <dynamics/>
      </axis>
    </joint>
    <plugin name='ros_model_plugin' filename='libros_model_plugin.so'/>
  </model>
</sdf>
