<sdf version='1.4'>
  <model name='autobed'>
    <link name='base_link'>
      <pose>1.070000 -0.000000 0.000000 0.000000 0.000000 0.000000</pose>
      <inertial>
        <pose>1.070000 -0.000000 0.000000 0.000000 0.000000 0.000000</pose>
        <mass>582.602000</mass>
        <inertia>
          <ixx>1.149270</ixx>
          <ixy>0.000000</ixy>
          <ixz>-0.000000</ixz>
          <iyy>6.704340</iyy>
          <iyz>-0.000000</iyz>
          <izz>7.797550</izz>
        </inertia>
      </inertial>
      <collision name='base_link_collision'>
        <pose>0.000000 0.000000 0.000000 0.000000 0.000000 0.000000</pose>
        <geometry>
          <mesh>
            <scale>1.000000 1.000000 1.000000</scale>
            <uri>model://autobed/meshes/base_link.STL</uri>
          </mesh>
        </geometry>
      </collision>
      <visual name='base_link_vis'>
        <pose>0.000000 0.000000 0.000000 0.000000 0.000000 0.000000</pose>
        <geometry>
          <mesh>
            <scale>1.000000 1.000000 1.000000</scale>
            <uri>model://autobed/meshes/base_link.STL</uri>
          </mesh>
        </geometry>
      </visual>
      <velocity_decay>
        <linear>0.000000</linear>
        <angular>0.000000</angular>
      </velocity_decay>
    </link>
    <joint name='X' type='revolute'>
      <child>base_link</child>
      <parent>world</parent>
      <axis>
        <limit>
          <lower>0.000000</lower>
          <upper>0.000000</upper>
        </limit>
        <dynamics>
          <damping>0.000000</damping>
        </dynamics>
        <xyz>0.000000 0.000000 1.000000</xyz>
      </axis>
    </joint>
    <link name='torso_lift_link'>
      <pose>1.050000 -0.000000 0.280500 0.000000 0.000000 0.000000</pose>
      <inertial>
        <pose>1.021450 0.017844 0.032190 0.000000 0.000000 0.000000</pose>
        <mass>18.377500</mass>
        <inertia>
          <ixx>13.156000</ixx>
          <ixy>0.078306</ixy>
          <ixz>-0.153939</ixz>
          <iyy>77.128700</iyy>
          <iyz>0.040070</iyz>
          <izz>82.099200</izz>
        </inertia>
      </inertial>
      <collision name='torso_lift_link_collision'>
        <pose>0.000000 0.000000 0.000000 0.000000 0.000000 0.000000</pose>
        <geometry>
          <mesh>
            <scale>1.000000 1.000000 1.000000</scale>
            <uri>model://autobed/meshes/torso_lift_link.STL</uri>
          </mesh>
        </geometry>
        <surface>
          <contact>
            <ode>
              <kp>1000000.000000</kp>
              <kd>1.000000</kd>
              <max_vel>1.000000</max_vel>
              <min_depth>0.000000</min_depth>
            </ode>
          </contact>
          <friction>
            <ode>
              <mu>1.500000</mu>
              <mu2>1.500000</mu2>
              <fdir1>1.000000 0.000000 0.000000</fdir1>
            </ode>
          </friction>
        </surface>
      </collision>
      <collision name='torso_lift_link_collision_mid_body_link'>
        <pose>0.782663 0.000000 0.050000 1.570800 0.000000 -1.570800</pose>
        <geometry>
          <mesh>
            <scale>1.000000 1.000000 1.000000</scale>
            <uri>model://autobed/meshes/mid_body_link.STL</uri>
          </mesh>
        </geometry>
        <surface>
          <contact>
            <ode>
              <kp>1000000.000000</kp>
              <kd>1.000000</kd>
              <max_vel>1.000000</max_vel>
              <min_depth>0.000000</min_depth>
            </ode>
          </contact>
          <friction>
            <ode>
              <mu>1.500000</mu>
              <mu2>1.500000</mu2>
              <fdir1>1.000000 0.000000 0.000000</fdir1>
            </ode>
          </friction>
        </surface>
      </collision>
      <visual name='torso_lift_link_vis'>
        <pose>0.000000 0.000000 0.000000 0.000000 0.000000 0.000000</pose>
        <geometry>
          <mesh>
            <scale>1.000000 1.000000 1.000000</scale>
            <uri>model://autobed/meshes/torso_lift_link.STL</uri>
          </mesh>
        </geometry>
      </visual>
      <visual name='torso_lift_link_vis_mid_body_link'>
        <pose>0.782663 0.000000 0.050000 1.570800 0.000000 -1.570800</pose>
        <geometry>
          <mesh>
            <scale>1.000000 1.000000 1.000000</scale>
            <uri>model://autobed/meshes/mid_body_link.STL</uri>
          </mesh>
        </geometry>
      </visual>
      <gravity>1</gravity>
      <velocity_decay>
        <linear>0.000000</linear>
        <angular>0.000000</angular>
      </velocity_decay>
      <self_collide>0</self_collide>
      <sensor name='torso_lift_link_pressuremat_sensor' type='contact'>
        <contact>
          <collision>torso_lift_link_collision</collision>
          <topic>__default_topic__</topic>
        </contact>
        <plugin name='ros_pressuremat_plugin_torso_lift_link' filename='libros_pressuremat_plugin.so'/>
        <always_on>1</always_on>
        <update_rate>30.000000</update_rate>
        <visualize>0</visualize>
      </sensor>
    </link>
    <joint name='autobed_height_joint' type='prismatic'>
      <child>torso_lift_link</child>
      <parent>base_link</parent>
      <axis>
        <xyz>0.000000 0.000000 1.000000</xyz>
        <limit>
          <lower>0.090000</lower>
          <upper>0.200000</upper>
          <effort>2000.000000</effort>
          <velocity>0.200000</velocity>
        </limit>
        <dynamics/>
      </axis>
    </joint>
    <link name='head_rest_link'>
      <pose>1.572660 -0.775000 0.330500 0.000004 0.000007 1.570800</pose>
      <inertial>
        <pose>-0.308081 0.000000 0.230046 0.000000 0.000000 0.000000</pose>
        <mass>15.215400</mass>
        <inertia>
          <ixx>14.522400</ixx>
          <ixy>-0.000000</ixy>
          <ixz>-2.971550</ixz>
          <iyy>6.584110</iyy>
          <iyz>-0.000000</iyz>
          <izz>13.292900</izz>
        </inertia>
      </inertial>
      <collision name='head_rest_link_collision'>
        <pose>0.000000 0.000000 0.000000 0.000000 0.000000 0.000000</pose>
        <geometry>
          <mesh>
            <scale>1.000000 1.000000 1.000000</scale>
            <uri>model://autobed/meshes/head_rest_link.STL</uri>
          </mesh>
        </geometry>
        <surface>
          <contact>
            <ode>
              <kp>1000000.000000</kp>
              <kd>1.000000</kd>
              <max_vel>1.000000</max_vel>
              <min_depth>0.000000</min_depth>
            </ode>
          </contact>
          <friction>
            <ode>
              <mu>1.500000</mu>
              <mu2>1.500000</mu2>
              <fdir1>1.000000 0.000000 0.000000</fdir1>
            </ode>
          </friction>
        </surface>
      </collision>
      <collision name='head_rest_link_collision_head_rest_spring'>
        <pose>0.000000 0.000000 0.000000 0.000000 0.000000 0.000000</pose>
        <geometry>
          <mesh>
            <scale>1.000000 1.000000 1.000000</scale>
            <uri>model://autobed/meshes/head_rest_spring.STL</uri>
          </mesh>
        </geometry>
        <surface>
          <contact>
            <ode>
              <kp>1000000.000000</kp>
              <kd>1.000000</kd>
              <max_vel>1.000000</max_vel>
              <min_depth>0.000000</min_depth>
            </ode>
          </contact>
          <friction>
            <ode>
              <mu>1.500000</mu>
              <mu2>1.500000</mu2>
              <fdir1>1.000000 0.000000 0.000000</fdir1>
            </ode>
          </friction>
        </surface>
      </collision>
      <visual name='head_rest_link_vis'>
        <pose>0.000000 0.000000 0.000000 0.000000 0.000000 0.000000</pose>
        <geometry>
          <mesh>
            <scale>1.000000 1.000000 1.000000</scale>
            <uri>model://autobed/meshes/head_rest_link.STL</uri>
          </mesh>
        </geometry>
      </visual>
      <visual name='head_rest_link_vis_head_rest_spring'>
        <pose>0.000000 0.000000 0.000000 0.000000 0.000000 0.000000</pose>
        <geometry>
          <mesh>
            <scale>1.000000 1.000000 1.000000</scale>
            <uri>model://autobed/meshes/head_rest_spring.STL</uri>
          </mesh>
        </geometry>
      </visual>
      <gravity>1</gravity>
      <velocity_decay>
        <linear>0.000000</linear>
        <angular>0.000000</angular>
      </velocity_decay>
      <self_collide>0</self_collide>
      <sensor name='head_rest_link_pressuremat_sensor' type='contact'>
        <contact>
          <collision>head_rest_link_collision</collision>
          <topic>__default_topic__</topic>
        </contact>
        <plugin name='ros_pressuremat_plugin_head_rest_link' filename='libros_pressuremat_plugin.so'/>
        <always_on>1</always_on>
        <update_rate>30.000000</update_rate>
        <visualize>0</visualize>
      </sensor>
    </link>
    <joint name='head_rest_hinge' type='revolute'>
      <child>head_rest_link</child>
      <parent>torso_lift_link</parent>
      <axis>
        <xyz>0.000004 0.000007 1.000000</xyz>
        <limit>
          <lower>0.000000</lower>
          <upper>1.570000</upper>
          <effort>2000.000000</effort>
          <velocity>0.200000</velocity>
        </limit>
        <dynamics/>
      </axis>
    </joint>
    <link name='leg_rest_upper_link'>
      <pose>2.112660 -0.000000 0.540500 -3.141590 -0.000000 0.000004</pose>
      <inertial>
        <pose>0.207405 0.000000 -0.031277 0.000000 0.000000 0.000000</pose>
        <mass>7.109550</mass>
        <inertia>
          <ixx>5.171270</ixx>
          <ixy>0.000000</ixy>
          <ixz>0.223272</ixz>
          <iyy>0.946523</iyy>
          <iyz>-0.000000</iyz>
          <izz>5.695750</izz>
        </inertia>
      </inertial>
      <collision name='leg_rest_upper_link_collision'>
        <pose>0.000000 0.000000 0.000000 0.000000 0.000000 0.000000</pose>
        <geometry>
          <mesh>
            <scale>1.000000 1.000000 1.000000</scale>
            <uri>model://autobed/meshes/leg_rest_upper_link.STL</uri>
          </mesh>
        </geometry>
        <surface>
          <contact>
            <ode>
              <kp>1000000.000000</kp>
              <kd>1.000000</kd>
              <max_vel>1.000000</max_vel>
              <min_depth>0.000000</min_depth>
            </ode>
          </contact>
          <friction>
            <ode>
              <mu>1.500000</mu>
              <mu2>1.500000</mu2>
              <fdir1>1.000000 0.000000 0.000000</fdir1>
            </ode>
          </friction>
        </surface>
      </collision>
      <collision name='leg_rest_upper_link_collision_leg_rest_upper_spring'>
        <pose>0.000000 0.000000 0.000000 0.000000 0.000000 0.000000</pose>
        <geometry>
          <mesh>
            <scale>1.000000 1.000000 1.000000</scale>
            <uri>model://autobed/meshes/leg_rest_upper_spring.STL</uri>
          </mesh>
        </geometry>
        <surface>
          <contact>
            <ode>
              <kp>1000000.000000</kp>
              <kd>1.000000</kd>
              <max_vel>1.000000</max_vel>
              <min_depth>0.000000</min_depth>
            </ode>
          </contact>
          <friction>
            <ode>
              <mu>1.500000</mu>
              <mu2>1.500000</mu2>
              <fdir1>1.000000 0.000000 0.000000</fdir1>
            </ode>
          </friction>
        </surface>
      </collision>
      <visual name='leg_rest_upper_link_vis'>
        <pose>0.000000 0.000000 0.000000 0.000000 0.000000 0.000000</pose>
        <geometry>
          <mesh>
            <scale>1.000000 1.000000 1.000000</scale>
            <uri>model://autobed/meshes/leg_rest_upper_link.STL</uri>
          </mesh>
        </geometry>
      </visual>
      <visual name='leg_rest_upper_link_vis_leg_rest_upper_spring'>
        <pose>0.000000 0.000000 0.000000 0.000000 0.000000 0.000000</pose>
        <geometry>
          <mesh>
            <scale>1.000000 1.000000 1.000000</scale>
            <uri>model://autobed/meshes/leg_rest_upper_spring.STL</uri>
          </mesh>
        </geometry>
      </visual>
      <gravity>1</gravity>
      <velocity_decay>
        <linear>0.000000</linear>
        <angular>0.000000</angular>
      </velocity_decay>
      <self_collide>0</self_collide>
      <sensor name='leg_rest_upper_link_pressuremat_sensor' type='contact'>
        <contact>
          <collision>leg_rest_upper_link_collision</collision>
          <topic>__default_topic__</topic>
        </contact>
        <plugin name='ros_pressuremat_plugin_leg_rest_upper_link' filename='libros_pressuremat_plugin.so'/>
        <always_on>1</always_on>
        <update_rate>30.000000</update_rate>
        <visualize>0</visualize>
      </sensor>
    </link>
    <joint name='leg_rest_upper_joint' type='revolute'>
      <child>leg_rest_upper_link</child>
      <parent>torso_lift_link</parent>
      <axis>
        <xyz>-0.000004 1.000000 0.000004</xyz>
        <limit>
          <lower>0.000000</lower>
          <upper>1.000000</upper>
          <effort>2000.000000</effort>
          <velocity>0.200000</velocity>
        </limit>
        <dynamics/>
      </axis>
    </joint>
    <link name='leg_rest_lower_link'>
      <pose>2.482660 0.000001 0.540500 -3.141590 -0.000000 0.000004</pose>
      <inertial>
        <pose>0.319834 -0.000000 -0.166115 0.000000 0.000000 0.000000</pose>
        <mass>13.274400</mass>
        <inertia>
          <ixx>9.670090</ixx>
          <ixy>-0.000000</ixy>
          <ixz>-0.918874</ixz>
          <iyy>5.509430</iyy>
          <iyz>-0.000000</iyz>
          <izz>14.339700</izz>
        </inertia>
      </inertial>
      <collision name='leg_rest_lower_link_collision'>
        <pose>0.000000 0.000000 0.000000 0.000000 0.000000 0.000000</pose>
        <geometry>
          <mesh>
            <scale>1.000000 1.000000 1.000000</scale>
            <uri>model://autobed/meshes/leg_rest_lower_link.STL</uri>
          </mesh>
        </geometry>
        <surface>
          <contact>
            <ode>
              <kp>1000000.000000</kp>
              <kd>1.000000</kd>
              <max_vel>1.000000</max_vel>
              <min_depth>0.000000</min_depth>
            </ode>
          </contact>
          <friction>
            <ode>
              <mu>1.500000</mu>
              <mu2>1.500000</mu2>
              <fdir1>1.000000 0.000000 0.000000</fdir1>
            </ode>
          </friction>
        </surface>
      </collision>
      <collision name='leg_rest_lower_link_collision_leg_rest_lower_spring'>
        <pose>0.000000 0.000000 0.000000 0.000000 0.000000 0.000000</pose>
        <geometry>
          <mesh>
            <scale>1.000000 1.000000 1.000000</scale>
            <uri>model://autobed/meshes/leg_rest_lower_spring.STL</uri>
          </mesh>
        </geometry>
        <surface>
          <contact>
            <ode>
              <kp>1000000.000000</kp>
              <kd>1.000000</kd>
              <max_vel>1.000000</max_vel>
              <min_depth>0.000000</min_depth>
            </ode>
          </contact>
          <friction>
            <ode>
              <mu>1.500000</mu>
              <mu2>1.500000</mu2>
              <fdir1>1.000000 0.000000 0.000000</fdir1>
            </ode>
          </friction>
        </surface>
      </collision>
      <visual name='leg_rest_lower_link_vis'>
        <pose>0.000000 0.000000 0.000000 0.000000 0.000000 0.000000</pose>
        <geometry>
          <mesh>
            <scale>1.000000 1.000000 1.000000</scale>
            <uri>model://autobed/meshes/leg_rest_lower_link.STL</uri>
          </mesh>
        </geometry>
      </visual>
      <visual name='leg_rest_lower_link_vis_leg_rest_lower_spring'>
        <pose>0.000000 0.000000 0.000000 0.000000 0.000000 0.000000</pose>
        <geometry>
          <mesh>
            <scale>1.000000 1.000000 1.000000</scale>
            <uri>model://autobed/meshes/leg_rest_lower_spring.STL</uri>
          </mesh>
        </geometry>
      </visual>
      <gravity>1</gravity>
      <velocity_decay>
        <linear>0.000000</linear>
        <angular>0.000000</angular>
      </velocity_decay>
      <self_collide>0</self_collide>
      <sensor name='leg_rest_lower_link_pressuremat_sensor' type='contact'>
        <contact>
          <collision>leg_rest_lower_link_collision</collision>
          <topic>__default_topic__</topic>
        </contact>
        <plugin name='ros_pressuremat_plugin_leg_rest_lower_link' filename='libros_pressuremat_plugin.so'/>
        <always_on>1</always_on>
        <update_rate>30.000000</update_rate>
        <visualize>0</visualize>
      </sensor>
    </link>
    <joint name='leg_rest_upper_lower_joint' type='revolute'>
      <child>leg_rest_lower_link</child>
      <parent>leg_rest_upper_link</parent>
      <axis>
        <xyz>-0.000000 0.000004 -1.000000</xyz>
        <limit>
          <lower>0.000000</lower>
          <upper>0.000000</upper>
          <effort>0.000000</effort>
          <velocity>0.000000</velocity>
        </limit>
        <dynamics/>
      </axis>
    </joint>
    <plugin name='ros_model_plugin' filename='libros_model_plugin.so'/>
  </model>
</sdf>
