<?xml version="1.0" ?>
<robot name="autobed">
  <gazebo reference="autobed">
    <plugin filename="libros_model_plugin.so" name="ros_model_plugin"/>
    <static> false </static>
  </gazebo>
  <gazebo reference="head_rest_link">
    <gravity>true</gravity>
   <!-- kp and kd for rubber -->
    <kp>1000000.0</kp>
    <kd>1.0</kd>
    <mu1>1.5</mu1>
    <mu2>1.5</mu2>
    <fdir1>1 0 0</fdir1>
    <maxVel>1.0</maxVel>
    <minDepth>0.00</minDepth>
    <sensor name="head_rest_link_pressuremat_sensor" type="contact">
      <contact>
        <collision>head_rest_link_collision</collision>
        <topic>__default_topic__</topic>
      </contact>
      <plugin filename="libros_pressuremat_plugin.so" name="ros_pressuremat_plugin_head_rest_link"/>
      <always_on>1</always_on>
      <update_rate>30.0</update_rate>
      <visualize>false</visualize>
    </sensor>
  </gazebo>
  <gazebo reference="torso_lift_link">
    <gravity>true</gravity>
    <!-- kp and kd for rubber -->
    <kp>1000000.0</kp>
    <kd>1.0</kd>
    <mu1>1.5</mu1>
    <mu2>1.5</mu2>
    <fdir1>1 0 0</fdir1>
    <maxVel>1.0</maxVel>
    <minDepth>0.00</minDepth>
   <sensor name="torso_lift_link_pressuremat_sensor" type="contact">
      <contact>
        <collision>torso_lift_link_collision</collision>
        <topic>__default_topic__</topic>
      </contact>
      <plugin filename="libros_pressuremat_plugin.so" name="ros_pressuremat_plugin_torso_lift_link"/>
      <always_on>1</always_on>
      <update_rate>30.0</update_rate>
      <visualize>false</visualize>
    </sensor>
  </gazebo>

  <gazebo reference="leg_rest_upper_link">
    <gravity>true</gravity>
    <!-- kp and kd for rubber -->
    <kp>1000000.0</kp>
    <kd>1.0</kd>
    <mu1>1.5</mu1>
    <mu2>1.5</mu2>
    <fdir1>1 0 0</fdir1>
    <maxVel>1.0</maxVel>
    <minDepth>0.00</minDepth>
   <sensor name="leg_rest_upper_link_pressuremat_sensor" type="contact">
      <contact>
        <collision>leg_rest_upper_link_collision</collision>
        <topic>__default_topic__</topic>
      </contact>
      <plugin filename="libros_pressuremat_plugin.so" name="ros_pressuremat_plugin_leg_rest_upper_link"/>
      <always_on>1</always_on>
      <update_rate>30.0</update_rate>
      <visualize>false</visualize>
    </sensor>
  </gazebo>

  <gazebo reference="leg_rest_lower_link">
    <gravity>true</gravity>
    <!-- kp and kd for rubber -->
    <kp>1000000.0</kp>
    <kd>1.0</kd>
    <mu1>1.5</mu1>
    <mu2>1.5</mu2>
    <fdir1>1 0 0</fdir1>
    <maxVel>1.0</maxVel>
    <minDepth>0.00</minDepth>

    <sensor name="leg_rest_lower_link_pressuremat_sensor" type="contact">
      <contact>
        <collision>leg_rest_lower_link_collision</collision>
        <topic>__default_topic__</topic>
      </contact>
      <plugin filename="libros_pressuremat_plugin.so" name="ros_pressuremat_plugin_leg_rest_lower_link"/>
      <always_on>1</always_on>
      <update_rate>30.0</update_rate>
      <visualize>false</visualize>
    </sensor>
  </gazebo>
  <link name="world"/>
  <joint name="X" type="fixed">
    <axis xyz="1 0 0"/>
    <origin rpy="0 0 0" xyz="1.07 -1.1433776843867E-16 0.0"/>
    <parent link="world"/>
    <child link="base_link"/>
    <limit effort="30" lower="-0.714601836603" upper="2.2853981634" velocity="3.48"/>
    <dynamics damping="10.0"/>
    <safety_controller k_position="100" k_velocity="10" soft_lower_limit="-0.564601836603" soft_upper_limit="2.1353981634"/>
  </joint>
  <link
    name="base_link">
    <inertial>
      <origin
        xyz="1.07 -1.1433776843867E-16 0.0"
        rpy="0 0 0" />
      <mass
        value="582.60172808288" />
      <inertia
        ixx="1.14927006759014"
        ixy="4.44089209850063E-16"
        ixz="-2.75515108570424E-16"
        iyy="6.70434113225239"
        iyz="-1.34851165646458E-15"
        izz="7.79754704731756" />
    </inertial>
    <visual>
      <origin
        xyz="0 0 0"
        rpy="0 0 0" />
      <geometry>
        <mesh
          filename="package://hrl_gazebo_autobed/urdf/meshes/base_link.STL" />
      </geometry>
      <material
        name="">
        <color
          rgba="0.792156862745098 0.819607843137255 0.933333333333333 1" />
      </material>
    </visual>
    <collision>
      <origin
        xyz="0 0 0"
        rpy="0 0 0" />
      <geometry>
        <mesh
          filename="package://hrl_gazebo_autobed/urdf/meshes/base_link.STL" />
      </geometry>
    </collision>
  </link>
  <link
    name="torso_lift_link">
    <inertial>
      <origin
        xyz="1.09 2.20819758781256E-16 0.0672692489591485"
        rpy="0 0 0" />
      <mass
        value="14.2783" />
      <inertia
        ixx="9.92907506560545"
        ixy="2.91752028352271E-14"
        ixz="3.71888182657881E-15"
        iyy="73.8016521218553"
        iyz="2.07859383954076E-15"
        izz="81.4226856770832" />
    </inertial>
    <visual>
      <origin
        xyz="0 0 0"
        rpy="0 0 0" />
      <geometry>
        <mesh
          filename="package://hrl_gazebo_autobed/urdf/meshes/torso_lift_link.STL" />
      </geometry>
      <material
        name="">
        <color
          rgba="0.792156862745098 0.819607843137255 0.933333333333333 1" />
      </material>
    </visual>
    <collision name="torso_lift_link_collision">
      <origin
        xyz="0 0 0"
        rpy="0 0 0" />
      <geometry>
        <mesh
          filename="package://hrl_gazebo_autobed/urdf/meshes/torso_lift_link.STL" />
      </geometry>
    </collision>
  </link>
  <joint
    name="autobed_height_joint"
    type="prismatic">
    <origin
      xyz="-0.02 0 0.2805"
      rpy="0 0 0" />
    <parent
      link="base_link" />
    <child
      link="torso_lift_link" />
    <axis
      xyz="0 0 1" />
    <limit
      lower="0.09"
      upper="0.2"
      effort="2000"
      velocity="0.2" />
  </joint>
  <link
    name="mid_body_link">
    <inertial>
      <origin
        xyz="1.8710748266729E-16 0.08 -0.14"
        rpy="0 0 0" />
      <mass
        value="4.0992" />
      <inertia
        ixx="0.355264"
        ixy="4.37857509439735E-16"
        ixz="-8.80386378148858E-16"
        iyy="3.127775"
        iyz="6.19830990237584E-17"
        izz="2.9474102" />
    </inertial>
    <visual>
      <origin
        xyz="0 0 0"
        rpy="0 0 0" />
      <geometry>
        <mesh
                filename="package://hrl_gazebo_autobed/urdf/meshes/mid_body_link.STL" />
      </geometry>
      <material
        name="">
        <color
          rgba="0.792156862745098 0.819607843137255 0.933333333333333 1" />
      </material>
    </visual>
    <collision>
      <origin
        xyz="0 0 0"
        rpy="0 0 0" />
      <geometry>
        <mesh
                filename="package://hrl_gazebo_autobed/urdf/meshes/mid_body_link.STL" />
      </geometry>
    </collision>
  </link>
  <joint
    name="mid_body_support"
    type="fixed">
    <origin
      xyz="0.782663137625778 0 0.0499999999999999"
      rpy="1.5707963267949 -8.02446817831858E-32 -1.5707963267949" />
    <parent
      link="torso_lift_link" />
    <child
      link="mid_body_link" />
    <axis
      xyz="0 0 0" />
  </joint>
  <link
    name="head_rest_link">
    <inertial>
      <origin
        xyz="-0.265125168782913 4.4043687850025E-16 0.300923176859995"
        rpy="0 0 0" />
      <mass
        value="5.2153755040103" />
      <inertia
        ixx="4.3520435272735"
        ixy="-6.37257789586883E-16"
        ixz="-0.817891944652799"
        iyy="1.75110482700463"
        iyz="-1.56812621946578E-15"
        izz="3.9218470936395" />
    </inertial>
    <visual>
      <origin
        xyz="0 0 0"
        rpy="0 0 0" />
      <geometry>
        <mesh
          filename="package://hrl_gazebo_autobed/urdf/meshes/head_rest_link.STL" />
      </geometry>
      <material
        name="">
        <color
          rgba="0.792156862745098 0.819607843137255 0.933333333333333 1" />
      </material>
    </visual>
    <collision name="head_rest_link_collision">
      <origin
        xyz="0 0 0"
        rpy="0 0 0" />
      <geometry>
        <mesh
          filename="package://hrl_gazebo_autobed/urdf/meshes/head_rest_link.STL" />
      </geometry>
    </collision>
  </link>
  <joint
    name="head_rest_hinge"
    type="revolute">
    <origin
      xyz="0.775 0 0.26"
      rpy="1.5708 1.0561E-10 3.1416" />
    <parent
      link="mid_body_link" />
    <child
      link="head_rest_link" />
    <axis
      xyz="0 0 1" />
    <limit
      lower="0"
      upper="1.57"
      effort="2000"
      velocity="0.2" />
  </joint>
  <link
    name="head_rest_spring">
    <inertial>
      <origin
        xyz="-0.330483974229218 4.31545596915377E-16 0.193081181832052"
        rpy="0 0 0" />
      <mass
        value="10.0" />
      <inertia
        ixx="10.1304498593177"
        ixy="-1.95205264327444E-15"
        ixz="-2.12949474795431"
        iyy="4.778496"
        iyz="-1.4014149363005E-15"
        izz="9.35641494068226" />
    </inertial>
    <visual>
      <origin
        xyz="0 0 0"
        rpy="0 0 0" />
      <geometry>
        <mesh
                filename="package://hrl_gazebo_autobed/urdf/meshes/head_rest_spring.STL" />
      </geometry>
      <material
        name="">
        <color
          rgba="0.792156862745098 0.819607843137255 0.933333333333333 1" />
      </material>
    </visual>
    <collision>
      <origin
        xyz="0 0 0"
        rpy="0 0 0" />
      <geometry>
        <mesh
                filename="package://hrl_gazebo_autobed/urdf/meshes/head_rest_spring.STL" />
      </geometry>
    </collision>
  </link>
  <joint
    name="head_support"
    type="fixed">
    <origin
      xyz="0 0 0"
      rpy="0 0 0" />
    <parent
      link="head_rest_link" />
    <child
      link="head_rest_spring" />
    <axis
      xyz="0 0 0" />
  </joint>
 
  <link
    name="leg_rest_upper_link">
    <inertial>
      <origin
        xyz="0.182707305037763 3.86279581056153E-16 0.0383150190635188"
        rpy="0 0 0" />
      <mass
        value="02.10955" />
      <inertia
        ixx="1.20574516349631"
        ixy="3.88338409378493E-17"
        ixz="0.0597579752356016"
        iyy="0.196641125"
        iyz="-2.44141358520896E-16"
        izz="1.35291699275369" />
    </inertial>
    <visual>
      <origin
        xyz="0 0 0"
        rpy="0 0 0" />
      <geometry>
        <mesh
          filename="package://hrl_gazebo_autobed/urdf/meshes/leg_rest_upper_link.STL" />
      </geometry>
      <material
        name="">
        <color
          rgba="0.792156862745098 0.819607843137255 0.933333333333333 1" />
      </material>
    </visual>
    <collision name="leg_rest_upper_link_collision">
      <origin
        xyz="0 0 0"
        rpy="0 0 0" />
      <geometry>
        <mesh
          filename="package://hrl_gazebo_autobed/urdf/meshes/leg_rest_upper_link.STL" />
      </geometry>
    </collision>
  </link>
  <joint
    name="leg_rest_upper_joint"
    type="revolute">
    <origin
      xyz="0 0.21 -0.28"
      rpy="1.5708 1.5708 0" />
    <parent
      link="mid_body_link" />
    <child
      link="leg_rest_upper_link" />
    <axis
      xyz="0 -1 0" />
    <limit
      lower="0"
      upper="1"
      effort="2000"
      velocity="0.2" />
  </joint>
  <link
    name="leg_rest_lower_link">
    <inertial>
      <origin
        xyz="0.334457721707061 -1.50857618804305E-16 -0.0882498294100081"
        rpy="0 0 0" />
      <mass
        value="3.25835" />
      <inertia
        ixx="2.25144692930096"
        ixy="-4.04280836598245E-16"
        ixz="-0.226007803318905"
        iyy="1.259017125"
        iyz="-2.82510221630701E-16"
        izz="3.41242022694904" />
    </inertial>
    <visual>
      <origin
        xyz="0 0 0"
        rpy="0 0 0" />
      <geometry>
        <mesh
          filename="package://hrl_gazebo_autobed/urdf/meshes/leg_rest_lower_link.STL" />
      </geometry>
      <material
        name="">
        <color
          rgba="0.792156862745098 0.819607843137255 0.933333333333333 1" />
      </material>
    </visual>
    <collision name="leg_rest_lower_link_collision">
      <origin
        xyz="0 0 0"
        rpy="0 0 0" />
      <geometry>
        <mesh
          filename="package://hrl_gazebo_autobed/urdf/meshes/leg_rest_lower_link.STL" />
      </geometry>
    </collision>
  </link>
  <joint
    name="leg_rest_upper_lower_joint"
    type="revolute">
    <origin
      xyz="0.37 0 0"
      rpy="-3.7123E-16 5.9121E-16 3.7854E-11" />
    <parent
      link="leg_rest_upper_link" />
    <child
      link="leg_rest_lower_link" />
    <axis
      xyz="0 0 1" />
    <limit
      lower="0"
      upper="0"
      effort="0"
      velocity="0" />
  </joint>
  <link
    name="leg_rest_lower_spring">
    <inertial>
      <origin
        xyz="0.315077040128518 -1.42119067021682E-16 -0.191445707143964"
        rpy="0 0 0" />
      <mass
        value="10.016" />
      <inertia
        ixx="7.39246105746224"
        ixy="-2.04710343003883E-16"
        ixz="-0.68794942833948"
        iyy="4.2233106"
        iyz="-1.08147874718548E-15"
        izz="10.9263696425378" />
    </inertial>
    <visual>
      <origin
        xyz="0 0 0"
        rpy="0 0 0" />
      <geometry>
        <mesh
                filename="package://hrl_gazebo_autobed/urdf/meshes/leg_rest_lower_spring.STL" />
      </geometry>
      <material
        name="">
        <color
          rgba="0.792156862745098 0.819607843137255 0.933333333333333 1" />
      </material>
    </visual>
    <collision>
      <origin
        xyz="0 0 0"
        rpy="0 0 0" />
      <geometry>
        <mesh
                filename="package://hrl_gazebo_autobed/urdf/meshes/leg_rest_lower_spring.STL" />
      </geometry>
    </collision>
  </link>
  <joint
    name="leg_rest_lower_support"
    type="fixed">
    <origin
      xyz="0 0 0"
      rpy="0 0 0" />
    <parent
      link="leg_rest_lower_link" />
    <child
      link="leg_rest_lower_spring" />
    <axis
      xyz="0 0 0" />
  </joint>
  <link
    name="leg_rest_upper_spring">
    <inertial>
      <origin
        xyz="0.217825695885058 4.63769251181149E-16 -0.0606379931411832"
        rpy="0 0 0" />
      <mass
        value="5.0" />
      <inertia
        ixx="3.95099347623326"
        ixy="2.08188694044973E-16"
        ixz="0.158358634373469"
        iyy="0.733525000000001"
        iyz="-6.8184306617181E-16"
        izz="4.34099882376675" />
    </inertial>
    <visual>
      <origin
        xyz="0 0 0"
        rpy="0 0 0" />
      <geometry>
        <mesh
                filename="package://hrl_gazebo_autobed/urdf/meshes/leg_rest_upper_spring.STL" />
      </geometry>
      <material
        name="">
        <color
          rgba="0.792156862745098 0.819607843137255 0.933333333333333 1" />
      </material>
    </visual>
    <collision>
      <origin
        xyz="0 0 0"
        rpy="0 0 0" />
      <geometry>
        <mesh
                filename="package://hrl_gazebo_autobed/urdf/meshes/leg_rest_upper_spring.STL" />
      </geometry>
    </collision>
  </link>
  <joint
    name="leg_rest_upper_support"
    type="fixed">
    <origin
      xyz="0 0 0"
      rpy="0 0 0" />
    <parent
      link="leg_rest_upper_link" />
    <child
      link="leg_rest_upper_spring" />
    <axis
      xyz="0 0 0" />
  </joint>

<!-- yash added transmissions -->
  <transmission name="autobed_height_t0" type="pr2_mechanism_model/SimpleTransmission">
    <actuator name="autobed_height_a0"/>
    <joint name="autobed_height_joint"/>
    <mechanicalReduction>1</mechanicalReduction>
  </transmission>
  <transmission name="head_rest_t0" type="pr2_mechanism_model/SimpleTransmission">
    <actuator name="head_rest_a0"/>
    <joint name="head_rest_hinge"/>
    <mechanicalReduction>1.0</mechanicalReduction>
  </transmission>
  <transmission name="leg_rest_t1" type="pr2_mechanism_model/SimpleTransmission">
    <actuator name="leg_rest_a1"/>
    <joint name="leg_rest_upper_joint"/>
    <mechanicalReduction>1.0</mechanicalReduction>
  </transmission>
</robot>
