<?xml version="1.0" ?>
<robot
  name="bed_and_body_v4">
  <link
    name="base_link">
    <inertial>
      <origin
        xyz="1.07 -9.52814736988918E-17 0.0654891108010717"
        rpy="0 0 0" />
      <mass
        value="5.8260172808288" />
      <inertia
        ixx="1.14927006759014"
        ixy="3.33066907387547E-16"
        ixz="-3.49761633492705E-16"
        iyy="6.70434113225239"
        iyz="-1.31815615371017E-15"
        izz="7.79754704731756" />
    </inertial>
    <visual>
      <origin
        xyz="0 0 0"
        rpy="0 0 0" />
      <geometry>
        <mesh
          filename="package://bed_and_body_v4/meshes/base_link.STL" />
      </geometry>
      <material
        name="">
        <color
          rgba="0.792156862745098 0.819607843137255 0.933333333333333 1" />
      </material>
    </visual>
    <collision>
      <origin
        xyz="0 0 0"
        rpy="0 0 0" />
      <geometry>
        <mesh
          filename="package://bed_and_body_v4/meshes/base_link.STL" />
      </geometry>
    </collision>
  </link>
  <link
    name="bed_frame_link">
    <inertial>
      <origin
        xyz="1.09 2.20819758781256E-16 0.0672692489591485"
        rpy="0 0 0" />
      <mass
        value="128.981" />
      <inertia
        ixx="9.92907506560545"
        ixy="2.91752028352271E-14"
        ixz="3.71888182657881E-15"
        iyy="73.8016521218553"
        iyz="2.07859383954076E-15"
        izz="81.4226856770832" />
    </inertial>
    <visual>
      <origin
        xyz="0 0 0"
        rpy="0 0 0" />
      <geometry>
        <mesh
          filename="package://bed_and_body_v4/meshes/bed_frame_link.STL" />
      </geometry>
      <material
        name="">
        <color
          rgba="0.792156862745098 0.819607843137255 0.933333333333333 1" />
      </material>
    </visual>
    <collision>
      <origin
        xyz="0 0 0"
        rpy="0 0 0" />
      <geometry>
        <mesh
          filename="package://bed_and_body_v4/meshes/bed_frame_link.STL" />
      </geometry>
    </collision>
  </link>
  <joint
    name="tele_legs_joint"
    type="prismatic">
    <origin
      xyz="-0.02 0 0.280500000000001"
      rpy="0 0 0" />
    <parent
      link="base_link" />
    <child
      link="bed_frame_link" />
    <axis
      xyz="0 0 -1" />
  </joint>
  <link
    name="mid_body_link">
    <inertial>
      <origin
        xyz="1.8710748266729E-16 0.08 -0.14"
        rpy="0 0 0" />
      <mass
        value="40.992" />
      <inertia
        ixx="0.355264"
        ixy="4.37857509439735E-16"
        ixz="-8.80386378148858E-16"
        iyy="3.127775"
        iyz="6.19830990237584E-17"
        izz="2.9474102" />
    </inertial>
    <visual>
      <origin
        xyz="0 0 0"
        rpy="0 0 0" />
      <geometry>
        <mesh
          filename="package://bed_and_body_v4/meshes/mid_body_link.STL" />
      </geometry>
      <material
        name="">
        <color
          rgba="0.792156862745098 0.819607843137255 0.933333333333333 1" />
      </material>
    </visual>
    <collision>
      <origin
        xyz="0 0 0"
        rpy="0 0 0" />
      <geometry>
        <mesh
          filename="package://bed_and_body_v4/meshes/mid_body_link.STL" />
      </geometry>
    </collision>
  </link>
  <joint
    name="mid_body_link"
    type="fixed">
    <origin
      xyz="0.782663137625778 0 0.0499999999999999"
      rpy="1.5707963267949 -8.02446817831858E-32 -1.5707963267949" />
    <parent
      link="bed_frame_link" />
    <child
      link="mid_body_link" />
    <axis
      xyz="0 0 0" />
  </joint>
  <link
    name="head_rest_link">
    <inertial>
      <origin
        xyz="-0.265125168782913 4.4043687850025E-16 0.300923176859995"
        rpy="0 0 0" />
      <mass
        value="46.745755040103" />
      <inertia
        ixx="4.3520435272735"
        ixy="-6.37257789586883E-16"
        ixz="-0.817891944652799"
        iyy="1.75110482700463"
        iyz="-1.56812621946578E-15"
        izz="3.9218470936395" />
    </inertial>
    <visual>
      <origin
        xyz="0 0 0"
        rpy="0 0 0" />
      <geometry>
        <mesh
          filename="package://bed_and_body_v4/meshes/head_rest_link.STL" />
      </geometry>
      <material
        name="">
        <color
          rgba="0.792156862745098 0.819607843137255 0.933333333333333 1" />
      </material>
    </visual>
    <collision>
      <origin
        xyz="0 0 0"
        rpy="0 0 0" />
      <geometry>
        <mesh
          filename="package://bed_and_body_v4/meshes/head_rest_link.STL" />
      </geometry>
    </collision>
  </link>
  <joint
    name="head_rest_hinge"
    type="revolute">
    <origin
      xyz="0 0.21 0"
      rpy="1.5708 1.5708 0" />
    <parent
      link="mid_body_link" />
    <child
      link="head_rest_link" />
    <axis
      xyz="0 -1 0" />
    <limit
      lower="0"
      upper="1.57"
      effort="0"
      velocity="0" />
  </joint>
  <link
    name="head_rest_spring">
    <inertial>
      <origin
        xyz="-0.330483974229218 4.31545596915377E-16 0.193081181832052"
        rpy="0 0 0" />
      <mass
        value="105.408" />
      <inertia
        ixx="10.1304498593177"
        ixy="-1.95205264327444E-15"
        ixz="-2.12949474795431"
        iyy="4.778496"
        iyz="-1.4014149363005E-15"
        izz="9.35641494068226" />
    </inertial>
    <visual>
      <origin
        xyz="0 0 0"
        rpy="0 0 0" />
      <geometry>
        <mesh
          filename="package://bed_and_body_v4/meshes/head_rest_spring.STL" />
      </geometry>
      <material
        name="">
        <color
          rgba="0.792156862745098 0.819607843137255 0.933333333333333 1" />
      </material>
    </visual>
    <collision>
      <origin
        xyz="0 0 0"
        rpy="0 0 0" />
      <geometry>
        <mesh
          filename="package://bed_and_body_v4/meshes/head_rest_spring.STL" />
      </geometry>
    </collision>
  </link>
  <joint
    name="head_support"
    type="fixed">
    <origin
      xyz="0 0 0"
      rpy="0 0 0" />
    <parent
      link="head_rest_link" />
    <child
      link="head_rest_spring" />
    <axis
      xyz="0 0 0" />
  </joint>
  <link
    name="leg_rest_upper_link">
    <inertial>
      <origin
        xyz="0.182707305037763 3.86279581056153E-16 0.0383150190635188"
        rpy="0 0 0" />
      <mass
        value="16.9275" />
      <inertia
        ixx="1.20574516349631"
        ixy="3.88338409378493E-17"
        ixz="0.0597579752356016"
        iyy="0.196641125"
        iyz="-2.44141358520896E-16"
        izz="1.35291699275369" />
    </inertial>
    <visual>
      <origin
        xyz="0 0 0"
        rpy="0 0 0" />
      <geometry>
        <mesh
          filename="package://bed_and_body_v4/meshes/leg_rest_upper_link.STL" />
      </geometry>
      <material
        name="">
        <color
          rgba="0.792156862745098 0.819607843137255 0.933333333333333 1" />
      </material>
    </visual>
    <collision>
      <origin
        xyz="0 0 0"
        rpy="0 0 0" />
      <geometry>
        <mesh
          filename="package://bed_and_body_v4/meshes/leg_rest_upper_link.STL" />
      </geometry>
    </collision>
  </link>
  <joint
    name="leg_rest_upper_joint"
    type="revolute">
    <origin
      xyz="0 0.21 -0.28"
      rpy="1.5708 1.5708 0" />
    <parent
      link="mid_body_link" />
    <child
      link="leg_rest_upper_link" />
    <axis
      xyz="0 -1 0" />
    <limit
      lower="0"
      upper="1"
      effort="0"
      velocity="0" />
  </joint>
  <link
    name="leg_rest_lower_link">
    <inertial>
      <origin
        xyz="0.334457721707061 -1.50857618804305E-16 -0.0882498294100081"
        rpy="0 0 0" />
      <mass
        value="31.5675" />
      <inertia
        ixx="2.25144692930096"
        ixy="-4.04280836598245E-16"
        ixz="-0.226007803318905"
        iyy="1.259017125"
        iyz="-2.82510221630701E-16"
        izz="3.41242022694904" />
    </inertial>
    <visual>
      <origin
        xyz="0 0 0"
        rpy="0 0 0" />
      <geometry>
        <mesh
          filename="package://bed_and_body_v4/meshes/leg_rest_lower_link.STL" />
      </geometry>
      <material
        name="">
        <color
          rgba="0.792156862745098 0.819607843137255 0.933333333333333 1" />
      </material>
    </visual>
    <collision>
      <origin
        xyz="0 0 0"
        rpy="0 0 0" />
      <geometry>
        <mesh
          filename="package://bed_and_body_v4/meshes/leg_rest_lower_link.STL" />
      </geometry>
    </collision>
  </link>
  <joint
    name="leg_rest_upper_lower_joint"
    type="revolute">
    <origin
      xyz="0.34869 0 0.12375"
      rpy="0 0 0" />
    <parent
      link="leg_rest_upper_link" />
    <child
      link="leg_rest_lower_link" />
    <axis
      xyz="0 -1 0" />
    <limit
      effort="0"
      velocity="0" />
  </joint>
  <link
    name="leg_rest_lower_spring">
    <inertial>
      <origin
        xyz="0.315077040128518 -1.42119067021682E-16 -0.191445707143964"
        rpy="0 0 0" />
      <mass
        value="101.016" />
      <inertia
        ixx="7.39246105746224"
        ixy="-2.04710343003883E-16"
        ixz="-0.68794942833948"
        iyy="4.2233106"
        iyz="-1.08147874718548E-15"
        izz="10.9263696425378" />
    </inertial>
    <visual>
      <origin
        xyz="0 0 0"
        rpy="0 0 0" />
      <geometry>
        <mesh
          filename="package://bed_and_body_v4/meshes/leg_rest_lower_spring.STL" />
      </geometry>
      <material
        name="">
        <color
          rgba="0.792156862745098 0.819607843137255 0.933333333333333 1" />
      </material>
    </visual>
    <collision>
      <origin
        xyz="0 0 0"
        rpy="0 0 0" />
      <geometry>
        <mesh
          filename="package://bed_and_body_v4/meshes/leg_rest_lower_spring.STL" />
      </geometry>
    </collision>
  </link>
  <joint
    name="leg_rest_lower_support"
    type="fixed">
    <origin
      xyz="0 0 0"
      rpy="0 0 0" />
    <parent
      link="leg_rest_lower_link" />
    <child
      link="leg_rest_lower_spring" />
    <axis
      xyz="0 0 0" />
  </joint>
  <link
    name="leg_rest_upper_spring">
    <inertial>
      <origin
        xyz="0.217825695885058 4.63769251181149E-16 -0.0606379931411832"
        rpy="0 0 0" />
      <mass
        value="54.168" />
      <inertia
        ixx="3.95099347623326"
        ixy="2.08188694044973E-16"
        ixz="0.158358634373469"
        iyy="0.733525000000001"
        iyz="-6.8184306617181E-16"
        izz="4.34099882376675" />
    </inertial>
    <visual>
      <origin
        xyz="0 0 0"
        rpy="0 0 0" />
      <geometry>
        <mesh
          filename="package://bed_and_body_v4/meshes/leg_rest_upper_spring.STL" />
      </geometry>
      <material
        name="">
        <color
          rgba="0.792156862745098 0.819607843137255 0.933333333333333 1" />
      </material>
    </visual>
    <collision>
      <origin
        xyz="0 0 0"
        rpy="0 0 0" />
      <geometry>
        <mesh
          filename="package://bed_and_body_v4/meshes/leg_rest_upper_spring.STL" />
      </geometry>
    </collision>
  </link>
  <joint
    name="leg_rest_upper_support"
    type="fixed">
    <origin
      xyz="0 0 0"
      rpy="0 0 0" />
    <parent
      link="leg_rest_upper_link" />
    <child
      link="leg_rest_upper_spring" />
    <axis
      xyz="0 0 0" />
  </joint>
</robot>
